Match Winner: Punjab Kings
Top Batsman: Shreyas Iyer (97 runs)
Top Wicket Taker: Ravisrinivasan Sai Kishore (3 wickets)
Updated results for match 83d70527-5fc4-4fad-8dd2-b88b385f379e: Winner - Punjab Kings, Top Batsman - Shreyas Iyer, Top Wicket Taker - Ravisrinivasan Sai Kishore
Match Winner: Lucknow Super Giants
Top Batsman: Nicholas Pooran (70 runs)
Top Wicket Taker: Shardul Thakur (4 wickets)
Updated results for match ab4e0813-1e78-467e-aca0-d80c5cfe7dbd: Winner - Lucknow Super Giants, Top Batsman - Nicholas Pooran, Top Wicket Taker - Shardul Thakur
Match Winner: Kolkata Knight Riders
Top Batsman: Quinton de Kock (97 runs)
Top Wicket Taker: Vaibhav Arora (2 wickets)
Updated results for match fd459f45-6e79-42c5-84e4-d046f291cacf: Winner - Kolkata Knight Riders, Top Batsman - Quinton de Kock, Top Wicket Taker - Vaibhav Arora
Match Winner: Royal Challengers Bengaluru
Top Batsman: Rajat Patidar (51 runs)
Top Wicket Taker: Noor Ahmad (3 wickets)
Updated results for match 7431523f-7ccb-4a4a-aed7-5c42fc08464c: Winner - Royal Challengers Bengaluru, Top Batsman - Rajat Patidar, Top Wicket Taker - Noor Ahmad
Match Winner: Royal Challengers Bengaluru
Top Batsman: Virat Kohli (59 runs)
Top Wicket Taker: Krunal Pandya (3 wickets)
Updated results for match cacf2d34-41b8-41dd-91ed-5183d880084c: Winner - Royal Challengers Bengaluru, Top Batsman - Virat Kohli, Top Wicket Taker - Krunal Pandya
Match Winner: Sunrisers Hyderabad
Top Batsman: Ishan Kishan (106 runs)
Top Wicket Taker: Tushar Deshpande (3 wickets)
Updated results for match 91b007f3-c0af-493f-808a-3f4ae2d66e33: Winner - Sunrisers Hyderabad, Top Batsman - Ishan Kishan, Top Wicket Taker - Tushar Deshpande
Match Winner: Chennai Super Kings
Top Batsman: Rachin Ravindra (65 runs)
Top Wicket Taker: Noor Ahmad (4 wickets)
Updated results for match 208d68e5-3fab-4f3b-88e9-29ec4a02d3e2: Winner - Chennai Super Kings, Top Batsman - Rachin Ravindra, Top Wicket Taker - Noor Ahmad
Match Winner: Delhi Capitals
Top Batsman: Nicholas Pooran (75 runs)
Top Wicket Taker: Mitchell Starc (3 wickets)
Updated results for match c6e97609-d9c1-46eb-805a-e282b34f3bb1: Winner - Delhi Capitals, Top Batsman - Nicholas Pooran, Top Wicket Taker - Mitchell Starc
Traceback (most recent call last):
  File "/home/siddharth/SixSense/venv/lib/python3.12/site-packages/httpx/_transports/default.py", line 101, in map_httpcore_exceptions
    yield
  File "/home/siddharth/SixSense/venv/lib/python3.12/site-packages/httpx/_transports/default.py", line 250, in handle_request
    resp = self._pool.handle_request(req)
           ^^^^^^^^^^^^^^^^^^^^^^^^^^^^^^
  File "/home/siddharth/SixSense/venv/lib/python3.12/site-packages/httpcore/_sync/connection_pool.py", line 256, in handle_request
    raise exc from None
  File "/home/siddharth/SixSense/venv/lib/python3.12/site-packages/httpcore/_sync/connection_pool.py", line 236, in handle_request
    response = connection.handle_request(
               ^^^^^^^^^^^^^^^^^^^^^^^^^^
  File "/home/siddharth/SixSense/venv/lib/python3.12/site-packages/httpcore/_sync/connection.py", line 101, in handle_request
    raise exc
  File "/home/siddharth/SixSense/venv/lib/python3.12/site-packages/httpcore/_sync/connection.py", line 78, in handle_request
    stream = self._connect(request)
             ^^^^^^^^^^^^^^^^^^^^^^
  File "/home/siddharth/SixSense/venv/lib/python3.12/site-packages/httpcore/_sync/connection.py", line 124, in _connect
    stream = self._network_backend.connect_tcp(**kwargs)
             ^^^^^^^^^^^^^^^^^^^^^^^^^^^^^^^^^^^^^^^^^^^
  File "/home/siddharth/SixSense/venv/lib/python3.12/site-packages/httpcore/_backends/sync.py", line 207, in connect_tcp
    with map_exceptions(exc_map):
  File "/usr/lib/python3.12/contextlib.py", line 158, in __exit__
    self.gen.throw(value)
  File "/home/siddharth/SixSense/venv/lib/python3.12/site-packages/httpcore/_exceptions.py", line 14, in map_exceptions
    raise to_exc(exc) from exc
httpcore.ConnectTimeout: timed out

The above exception was the direct cause of the following exception:

Traceback (most recent call last):
  File "/home/siddharth/SixSense/Scraping/player_details.py", line 88, in <module>
    update_match_results()
  File "/home/siddharth/SixSense/Scraping/player_details.py", line 70, in update_match_results
    match_ids = get_completed_matches()
                ^^^^^^^^^^^^^^^^^^^^^^^
  File "/home/siddharth/SixSense/Scraping/player_details.py", line 18, in get_completed_matches
    response = supabase.table("matches").select("match_id").eq("status", "completed").execute()
               ^^^^^^^^^^^^^^^^^^^^^^^^^^^^^^^^^^^^^^^^^^^^^^^^^^^^^^^^^^^^^^^^^^^^^^^^^^^^^^^^
  File "/home/siddharth/SixSense/venv/lib/python3.12/site-packages/postgrest/_sync/request_builder.py", line 58, in execute
    r = self.session.request(
        ^^^^^^^^^^^^^^^^^^^^^
  File "/home/siddharth/SixSense/venv/lib/python3.12/site-packages/httpx/_client.py", line 825, in request
    return self.send(request, auth=auth, follow_redirects=follow_redirects)
           ^^^^^^^^^^^^^^^^^^^^^^^^^^^^^^^^^^^^^^^^^^^^^^^^^^^^^^^^^^^^^^^^
  File "/home/siddharth/SixSense/venv/lib/python3.12/site-packages/httpx/_client.py", line 914, in send
    response = self._send_handling_auth(
               ^^^^^^^^^^^^^^^^^^^^^^^^^
  File "/home/siddharth/SixSense/venv/lib/python3.12/site-packages/httpx/_client.py", line 942, in _send_handling_auth
    response = self._send_handling_redirects(
               ^^^^^^^^^^^^^^^^^^^^^^^^^^^^^^
  File "/home/siddharth/SixSense/venv/lib/python3.12/site-packages/httpx/_client.py", line 979, in _send_handling_redirects
    response = self._send_single_request(request)
               ^^^^^^^^^^^^^^^^^^^^^^^^^^^^^^^^^^
  File "/home/siddharth/SixSense/venv/lib/python3.12/site-packages/httpx/_client.py", line 1014, in _send_single_request
    response = transport.handle_request(request)
               ^^^^^^^^^^^^^^^^^^^^^^^^^^^^^^^^^
  File "/home/siddharth/SixSense/venv/lib/python3.12/site-packages/httpx/_transports/default.py", line 249, in handle_request
    with map_httpcore_exceptions():
  File "/usr/lib/python3.12/contextlib.py", line 158, in __exit__
    self.gen.throw(value)
  File "/home/siddharth/SixSense/venv/lib/python3.12/site-packages/httpx/_transports/default.py", line 118, in map_httpcore_exceptions
    raise mapped_exc(message) from exc
httpx.ConnectTimeout: timed out
Traceback (most recent call last):
  File "/home/siddharth/SixSense/venv/lib/python3.12/site-packages/httpx/_transports/default.py", line 101, in map_httpcore_exceptions
    yield
  File "/home/siddharth/SixSense/venv/lib/python3.12/site-packages/httpx/_transports/default.py", line 250, in handle_request
    resp = self._pool.handle_request(req)
           ^^^^^^^^^^^^^^^^^^^^^^^^^^^^^^
  File "/home/siddharth/SixSense/venv/lib/python3.12/site-packages/httpcore/_sync/connection_pool.py", line 256, in handle_request
    raise exc from None
  File "/home/siddharth/SixSense/venv/lib/python3.12/site-packages/httpcore/_sync/connection_pool.py", line 236, in handle_request
    response = connection.handle_request(
               ^^^^^^^^^^^^^^^^^^^^^^^^^^
  File "/home/siddharth/SixSense/venv/lib/python3.12/site-packages/httpcore/_sync/connection.py", line 101, in handle_request
    raise exc
  File "/home/siddharth/SixSense/venv/lib/python3.12/site-packages/httpcore/_sync/connection.py", line 78, in handle_request
    stream = self._connect(request)
             ^^^^^^^^^^^^^^^^^^^^^^
  File "/home/siddharth/SixSense/venv/lib/python3.12/site-packages/httpcore/_sync/connection.py", line 124, in _connect
    stream = self._network_backend.connect_tcp(**kwargs)
             ^^^^^^^^^^^^^^^^^^^^^^^^^^^^^^^^^^^^^^^^^^^
  File "/home/siddharth/SixSense/venv/lib/python3.12/site-packages/httpcore/_backends/sync.py", line 207, in connect_tcp
    with map_exceptions(exc_map):
  File "/usr/lib/python3.12/contextlib.py", line 158, in __exit__
    self.gen.throw(value)
  File "/home/siddharth/SixSense/venv/lib/python3.12/site-packages/httpcore/_exceptions.py", line 14, in map_exceptions
    raise to_exc(exc) from exc
httpcore.ConnectTimeout: timed out

The above exception was the direct cause of the following exception:

Traceback (most recent call last):
  File "/home/siddharth/SixSense/Scraping/player_details.py", line 88, in <module>
    update_match_results()
  File "/home/siddharth/SixSense/Scraping/player_details.py", line 70, in update_match_results
    match_ids = get_completed_matches()
                ^^^^^^^^^^^^^^^^^^^^^^^
  File "/home/siddharth/SixSense/Scraping/player_details.py", line 18, in get_completed_matches
    response = supabase.table("matches").select("match_id").eq("status", "completed").execute()
               ^^^^^^^^^^^^^^^^^^^^^^^^^^^^^^^^^^^^^^^^^^^^^^^^^^^^^^^^^^^^^^^^^^^^^^^^^^^^^^^^
  File "/home/siddharth/SixSense/venv/lib/python3.12/site-packages/postgrest/_sync/request_builder.py", line 58, in execute
    r = self.session.request(
        ^^^^^^^^^^^^^^^^^^^^^
  File "/home/siddharth/SixSense/venv/lib/python3.12/site-packages/httpx/_client.py", line 825, in request
    return self.send(request, auth=auth, follow_redirects=follow_redirects)
           ^^^^^^^^^^^^^^^^^^^^^^^^^^^^^^^^^^^^^^^^^^^^^^^^^^^^^^^^^^^^^^^^
  File "/home/siddharth/SixSense/venv/lib/python3.12/site-packages/httpx/_client.py", line 914, in send
    response = self._send_handling_auth(
               ^^^^^^^^^^^^^^^^^^^^^^^^^
  File "/home/siddharth/SixSense/venv/lib/python3.12/site-packages/httpx/_client.py", line 942, in _send_handling_auth
    response = self._send_handling_redirects(
               ^^^^^^^^^^^^^^^^^^^^^^^^^^^^^^
  File "/home/siddharth/SixSense/venv/lib/python3.12/site-packages/httpx/_client.py", line 979, in _send_handling_redirects
    response = self._send_single_request(request)
               ^^^^^^^^^^^^^^^^^^^^^^^^^^^^^^^^^^
  File "/home/siddharth/SixSense/venv/lib/python3.12/site-packages/httpx/_client.py", line 1014, in _send_single_request
    response = transport.handle_request(request)
               ^^^^^^^^^^^^^^^^^^^^^^^^^^^^^^^^^
  File "/home/siddharth/SixSense/venv/lib/python3.12/site-packages/httpx/_transports/default.py", line 249, in handle_request
    with map_httpcore_exceptions():
  File "/usr/lib/python3.12/contextlib.py", line 158, in __exit__
    self.gen.throw(value)
  File "/home/siddharth/SixSense/venv/lib/python3.12/site-packages/httpx/_transports/default.py", line 118, in map_httpcore_exceptions
    raise mapped_exc(message) from exc
httpx.ConnectTimeout: timed out
Traceback (most recent call last):
  File "/home/siddharth/SixSense/venv/lib/python3.12/site-packages/httpx/_transports/default.py", line 101, in map_httpcore_exceptions
    yield
  File "/home/siddharth/SixSense/venv/lib/python3.12/site-packages/httpx/_transports/default.py", line 250, in handle_request
    resp = self._pool.handle_request(req)
           ^^^^^^^^^^^^^^^^^^^^^^^^^^^^^^
  File "/home/siddharth/SixSense/venv/lib/python3.12/site-packages/httpcore/_sync/connection_pool.py", line 256, in handle_request
    raise exc from None
  File "/home/siddharth/SixSense/venv/lib/python3.12/site-packages/httpcore/_sync/connection_pool.py", line 236, in handle_request
    response = connection.handle_request(
               ^^^^^^^^^^^^^^^^^^^^^^^^^^
  File "/home/siddharth/SixSense/venv/lib/python3.12/site-packages/httpcore/_sync/connection.py", line 101, in handle_request
    raise exc
  File "/home/siddharth/SixSense/venv/lib/python3.12/site-packages/httpcore/_sync/connection.py", line 78, in handle_request
    stream = self._connect(request)
             ^^^^^^^^^^^^^^^^^^^^^^
  File "/home/siddharth/SixSense/venv/lib/python3.12/site-packages/httpcore/_sync/connection.py", line 124, in _connect
    stream = self._network_backend.connect_tcp(**kwargs)
             ^^^^^^^^^^^^^^^^^^^^^^^^^^^^^^^^^^^^^^^^^^^
  File "/home/siddharth/SixSense/venv/lib/python3.12/site-packages/httpcore/_backends/sync.py", line 207, in connect_tcp
    with map_exceptions(exc_map):
  File "/usr/lib/python3.12/contextlib.py", line 158, in __exit__
    self.gen.throw(value)
  File "/home/siddharth/SixSense/venv/lib/python3.12/site-packages/httpcore/_exceptions.py", line 14, in map_exceptions
    raise to_exc(exc) from exc
httpcore.ConnectTimeout: timed out

The above exception was the direct cause of the following exception:

Traceback (most recent call last):
  File "/home/siddharth/SixSense/Scraping/player_details.py", line 88, in <module>
    update_match_results()
  File "/home/siddharth/SixSense/Scraping/player_details.py", line 70, in update_match_results
    match_ids = get_completed_matches()
                ^^^^^^^^^^^^^^^^^^^^^^^
  File "/home/siddharth/SixSense/Scraping/player_details.py", line 18, in get_completed_matches
    response = supabase.table("matches").select("match_id").eq("status", "completed").execute()
               ^^^^^^^^^^^^^^^^^^^^^^^^^^^^^^^^^^^^^^^^^^^^^^^^^^^^^^^^^^^^^^^^^^^^^^^^^^^^^^^^
  File "/home/siddharth/SixSense/venv/lib/python3.12/site-packages/postgrest/_sync/request_builder.py", line 58, in execute
    r = self.session.request(
        ^^^^^^^^^^^^^^^^^^^^^
  File "/home/siddharth/SixSense/venv/lib/python3.12/site-packages/httpx/_client.py", line 825, in request
    return self.send(request, auth=auth, follow_redirects=follow_redirects)
           ^^^^^^^^^^^^^^^^^^^^^^^^^^^^^^^^^^^^^^^^^^^^^^^^^^^^^^^^^^^^^^^^
  File "/home/siddharth/SixSense/venv/lib/python3.12/site-packages/httpx/_client.py", line 914, in send
    response = self._send_handling_auth(
               ^^^^^^^^^^^^^^^^^^^^^^^^^
  File "/home/siddharth/SixSense/venv/lib/python3.12/site-packages/httpx/_client.py", line 942, in _send_handling_auth
    response = self._send_handling_redirects(
               ^^^^^^^^^^^^^^^^^^^^^^^^^^^^^^
  File "/home/siddharth/SixSense/venv/lib/python3.12/site-packages/httpx/_client.py", line 979, in _send_handling_redirects
    response = self._send_single_request(request)
               ^^^^^^^^^^^^^^^^^^^^^^^^^^^^^^^^^^
  File "/home/siddharth/SixSense/venv/lib/python3.12/site-packages/httpx/_client.py", line 1014, in _send_single_request
    response = transport.handle_request(request)
               ^^^^^^^^^^^^^^^^^^^^^^^^^^^^^^^^^
  File "/home/siddharth/SixSense/venv/lib/python3.12/site-packages/httpx/_transports/default.py", line 249, in handle_request
    with map_httpcore_exceptions():
  File "/usr/lib/python3.12/contextlib.py", line 158, in __exit__
    self.gen.throw(value)
  File "/home/siddharth/SixSense/venv/lib/python3.12/site-packages/httpx/_transports/default.py", line 118, in map_httpcore_exceptions
    raise mapped_exc(message) from exc
httpx.ConnectTimeout: timed out
Traceback (most recent call last):
  File "/home/siddharth/SixSense/venv/lib/python3.12/site-packages/httpx/_transports/default.py", line 101, in map_httpcore_exceptions
    yield
  File "/home/siddharth/SixSense/venv/lib/python3.12/site-packages/httpx/_transports/default.py", line 250, in handle_request
    resp = self._pool.handle_request(req)
           ^^^^^^^^^^^^^^^^^^^^^^^^^^^^^^
  File "/home/siddharth/SixSense/venv/lib/python3.12/site-packages/httpcore/_sync/connection_pool.py", line 256, in handle_request
    raise exc from None
  File "/home/siddharth/SixSense/venv/lib/python3.12/site-packages/httpcore/_sync/connection_pool.py", line 236, in handle_request
    response = connection.handle_request(
               ^^^^^^^^^^^^^^^^^^^^^^^^^^
  File "/home/siddharth/SixSense/venv/lib/python3.12/site-packages/httpcore/_sync/connection.py", line 101, in handle_request
    raise exc
  File "/home/siddharth/SixSense/venv/lib/python3.12/site-packages/httpcore/_sync/connection.py", line 78, in handle_request
    stream = self._connect(request)
             ^^^^^^^^^^^^^^^^^^^^^^
  File "/home/siddharth/SixSense/venv/lib/python3.12/site-packages/httpcore/_sync/connection.py", line 124, in _connect
    stream = self._network_backend.connect_tcp(**kwargs)
             ^^^^^^^^^^^^^^^^^^^^^^^^^^^^^^^^^^^^^^^^^^^
  File "/home/siddharth/SixSense/venv/lib/python3.12/site-packages/httpcore/_backends/sync.py", line 207, in connect_tcp
    with map_exceptions(exc_map):
  File "/usr/lib/python3.12/contextlib.py", line 158, in __exit__
    self.gen.throw(value)
  File "/home/siddharth/SixSense/venv/lib/python3.12/site-packages/httpcore/_exceptions.py", line 14, in map_exceptions
    raise to_exc(exc) from exc
httpcore.ConnectTimeout: timed out

The above exception was the direct cause of the following exception:

Traceback (most recent call last):
  File "/home/siddharth/SixSense/Scraping/player_details.py", line 88, in <module>
    update_match_results()
  File "/home/siddharth/SixSense/Scraping/player_details.py", line 70, in update_match_results
    match_ids = get_completed_matches()
                ^^^^^^^^^^^^^^^^^^^^^^^
  File "/home/siddharth/SixSense/Scraping/player_details.py", line 18, in get_completed_matches
    response = supabase.table("matches").select("match_id").eq("status", "completed").execute()
               ^^^^^^^^^^^^^^^^^^^^^^^^^^^^^^^^^^^^^^^^^^^^^^^^^^^^^^^^^^^^^^^^^^^^^^^^^^^^^^^^
  File "/home/siddharth/SixSense/venv/lib/python3.12/site-packages/postgrest/_sync/request_builder.py", line 58, in execute
    r = self.session.request(
        ^^^^^^^^^^^^^^^^^^^^^
  File "/home/siddharth/SixSense/venv/lib/python3.12/site-packages/httpx/_client.py", line 825, in request
    return self.send(request, auth=auth, follow_redirects=follow_redirects)
           ^^^^^^^^^^^^^^^^^^^^^^^^^^^^^^^^^^^^^^^^^^^^^^^^^^^^^^^^^^^^^^^^
  File "/home/siddharth/SixSense/venv/lib/python3.12/site-packages/httpx/_client.py", line 914, in send
    response = self._send_handling_auth(
               ^^^^^^^^^^^^^^^^^^^^^^^^^
  File "/home/siddharth/SixSense/venv/lib/python3.12/site-packages/httpx/_client.py", line 942, in _send_handling_auth
    response = self._send_handling_redirects(
               ^^^^^^^^^^^^^^^^^^^^^^^^^^^^^^
  File "/home/siddharth/SixSense/venv/lib/python3.12/site-packages/httpx/_client.py", line 979, in _send_handling_redirects
    response = self._send_single_request(request)
               ^^^^^^^^^^^^^^^^^^^^^^^^^^^^^^^^^^
  File "/home/siddharth/SixSense/venv/lib/python3.12/site-packages/httpx/_client.py", line 1014, in _send_single_request
    response = transport.handle_request(request)
               ^^^^^^^^^^^^^^^^^^^^^^^^^^^^^^^^^
  File "/home/siddharth/SixSense/venv/lib/python3.12/site-packages/httpx/_transports/default.py", line 249, in handle_request
    with map_httpcore_exceptions():
  File "/usr/lib/python3.12/contextlib.py", line 158, in __exit__
    self.gen.throw(value)
  File "/home/siddharth/SixSense/venv/lib/python3.12/site-packages/httpx/_transports/default.py", line 118, in map_httpcore_exceptions
    raise mapped_exc(message) from exc
httpx.ConnectTimeout: timed out
Traceback (most recent call last):
  File "/home/siddharth/SixSense/venv/lib/python3.12/site-packages/httpx/_transports/default.py", line 101, in map_httpcore_exceptions
    yield
  File "/home/siddharth/SixSense/venv/lib/python3.12/site-packages/httpx/_transports/default.py", line 250, in handle_request
    resp = self._pool.handle_request(req)
           ^^^^^^^^^^^^^^^^^^^^^^^^^^^^^^
  File "/home/siddharth/SixSense/venv/lib/python3.12/site-packages/httpcore/_sync/connection_pool.py", line 256, in handle_request
    raise exc from None
  File "/home/siddharth/SixSense/venv/lib/python3.12/site-packages/httpcore/_sync/connection_pool.py", line 236, in handle_request
    response = connection.handle_request(
               ^^^^^^^^^^^^^^^^^^^^^^^^^^
  File "/home/siddharth/SixSense/venv/lib/python3.12/site-packages/httpcore/_sync/connection.py", line 101, in handle_request
    raise exc
  File "/home/siddharth/SixSense/venv/lib/python3.12/site-packages/httpcore/_sync/connection.py", line 78, in handle_request
    stream = self._connect(request)
             ^^^^^^^^^^^^^^^^^^^^^^
  File "/home/siddharth/SixSense/venv/lib/python3.12/site-packages/httpcore/_sync/connection.py", line 124, in _connect
    stream = self._network_backend.connect_tcp(**kwargs)
             ^^^^^^^^^^^^^^^^^^^^^^^^^^^^^^^^^^^^^^^^^^^
  File "/home/siddharth/SixSense/venv/lib/python3.12/site-packages/httpcore/_backends/sync.py", line 207, in connect_tcp
    with map_exceptions(exc_map):
  File "/usr/lib/python3.12/contextlib.py", line 158, in __exit__
    self.gen.throw(value)
  File "/home/siddharth/SixSense/venv/lib/python3.12/site-packages/httpcore/_exceptions.py", line 14, in map_exceptions
    raise to_exc(exc) from exc
httpcore.ConnectTimeout: timed out

The above exception was the direct cause of the following exception:

Traceback (most recent call last):
  File "/home/siddharth/SixSense/Scraping/player_details.py", line 88, in <module>
    update_match_results()
  File "/home/siddharth/SixSense/Scraping/player_details.py", line 70, in update_match_results
    match_ids = get_completed_matches()
                ^^^^^^^^^^^^^^^^^^^^^^^
  File "/home/siddharth/SixSense/Scraping/player_details.py", line 18, in get_completed_matches
    response = supabase.table("matches").select("match_id").eq("status", "completed").execute()
               ^^^^^^^^^^^^^^^^^^^^^^^^^^^^^^^^^^^^^^^^^^^^^^^^^^^^^^^^^^^^^^^^^^^^^^^^^^^^^^^^
  File "/home/siddharth/SixSense/venv/lib/python3.12/site-packages/postgrest/_sync/request_builder.py", line 58, in execute
    r = self.session.request(
        ^^^^^^^^^^^^^^^^^^^^^
  File "/home/siddharth/SixSense/venv/lib/python3.12/site-packages/httpx/_client.py", line 825, in request
    return self.send(request, auth=auth, follow_redirects=follow_redirects)
           ^^^^^^^^^^^^^^^^^^^^^^^^^^^^^^^^^^^^^^^^^^^^^^^^^^^^^^^^^^^^^^^^
  File "/home/siddharth/SixSense/venv/lib/python3.12/site-packages/httpx/_client.py", line 914, in send
    response = self._send_handling_auth(
               ^^^^^^^^^^^^^^^^^^^^^^^^^
  File "/home/siddharth/SixSense/venv/lib/python3.12/site-packages/httpx/_client.py", line 942, in _send_handling_auth
    response = self._send_handling_redirects(
               ^^^^^^^^^^^^^^^^^^^^^^^^^^^^^^
  File "/home/siddharth/SixSense/venv/lib/python3.12/site-packages/httpx/_client.py", line 979, in _send_handling_redirects
    response = self._send_single_request(request)
               ^^^^^^^^^^^^^^^^^^^^^^^^^^^^^^^^^^
  File "/home/siddharth/SixSense/venv/lib/python3.12/site-packages/httpx/_client.py", line 1014, in _send_single_request
    response = transport.handle_request(request)
               ^^^^^^^^^^^^^^^^^^^^^^^^^^^^^^^^^
  File "/home/siddharth/SixSense/venv/lib/python3.12/site-packages/httpx/_transports/default.py", line 249, in handle_request
    with map_httpcore_exceptions():
  File "/usr/lib/python3.12/contextlib.py", line 158, in __exit__
    self.gen.throw(value)
  File "/home/siddharth/SixSense/venv/lib/python3.12/site-packages/httpx/_transports/default.py", line 118, in map_httpcore_exceptions
    raise mapped_exc(message) from exc
httpx.ConnectTimeout: timed out
Traceback (most recent call last):
  File "/home/siddharth/SixSense/venv/lib/python3.12/site-packages/httpx/_transports/default.py", line 101, in map_httpcore_exceptions
    yield
  File "/home/siddharth/SixSense/venv/lib/python3.12/site-packages/httpx/_transports/default.py", line 250, in handle_request
    resp = self._pool.handle_request(req)
           ^^^^^^^^^^^^^^^^^^^^^^^^^^^^^^
  File "/home/siddharth/SixSense/venv/lib/python3.12/site-packages/httpcore/_sync/connection_pool.py", line 256, in handle_request
    raise exc from None
  File "/home/siddharth/SixSense/venv/lib/python3.12/site-packages/httpcore/_sync/connection_pool.py", line 236, in handle_request
    response = connection.handle_request(
               ^^^^^^^^^^^^^^^^^^^^^^^^^^
  File "/home/siddharth/SixSense/venv/lib/python3.12/site-packages/httpcore/_sync/connection.py", line 101, in handle_request
    raise exc
  File "/home/siddharth/SixSense/venv/lib/python3.12/site-packages/httpcore/_sync/connection.py", line 78, in handle_request
    stream = self._connect(request)
             ^^^^^^^^^^^^^^^^^^^^^^
  File "/home/siddharth/SixSense/venv/lib/python3.12/site-packages/httpcore/_sync/connection.py", line 124, in _connect
    stream = self._network_backend.connect_tcp(**kwargs)
             ^^^^^^^^^^^^^^^^^^^^^^^^^^^^^^^^^^^^^^^^^^^
  File "/home/siddharth/SixSense/venv/lib/python3.12/site-packages/httpcore/_backends/sync.py", line 207, in connect_tcp
    with map_exceptions(exc_map):
  File "/usr/lib/python3.12/contextlib.py", line 158, in __exit__
    self.gen.throw(value)
  File "/home/siddharth/SixSense/venv/lib/python3.12/site-packages/httpcore/_exceptions.py", line 14, in map_exceptions
    raise to_exc(exc) from exc
httpcore.ConnectTimeout: timed out

The above exception was the direct cause of the following exception:

Traceback (most recent call last):
  File "/home/siddharth/SixSense/Scraping/player_details.py", line 88, in <module>
    update_match_results()
  File "/home/siddharth/SixSense/Scraping/player_details.py", line 70, in update_match_results
    match_ids = get_completed_matches()
                ^^^^^^^^^^^^^^^^^^^^^^^
  File "/home/siddharth/SixSense/Scraping/player_details.py", line 18, in get_completed_matches
    response = supabase.table("matches").select("match_id").eq("status", "completed").execute()
               ^^^^^^^^^^^^^^^^^^^^^^^^^^^^^^^^^^^^^^^^^^^^^^^^^^^^^^^^^^^^^^^^^^^^^^^^^^^^^^^^
  File "/home/siddharth/SixSense/venv/lib/python3.12/site-packages/postgrest/_sync/request_builder.py", line 58, in execute
    r = self.session.request(
        ^^^^^^^^^^^^^^^^^^^^^
  File "/home/siddharth/SixSense/venv/lib/python3.12/site-packages/httpx/_client.py", line 825, in request
    return self.send(request, auth=auth, follow_redirects=follow_redirects)
           ^^^^^^^^^^^^^^^^^^^^^^^^^^^^^^^^^^^^^^^^^^^^^^^^^^^^^^^^^^^^^^^^
  File "/home/siddharth/SixSense/venv/lib/python3.12/site-packages/httpx/_client.py", line 914, in send
    response = self._send_handling_auth(
               ^^^^^^^^^^^^^^^^^^^^^^^^^
  File "/home/siddharth/SixSense/venv/lib/python3.12/site-packages/httpx/_client.py", line 942, in _send_handling_auth
    response = self._send_handling_redirects(
               ^^^^^^^^^^^^^^^^^^^^^^^^^^^^^^
  File "/home/siddharth/SixSense/venv/lib/python3.12/site-packages/httpx/_client.py", line 979, in _send_handling_redirects
    response = self._send_single_request(request)
               ^^^^^^^^^^^^^^^^^^^^^^^^^^^^^^^^^^
  File "/home/siddharth/SixSense/venv/lib/python3.12/site-packages/httpx/_client.py", line 1014, in _send_single_request
    response = transport.handle_request(request)
               ^^^^^^^^^^^^^^^^^^^^^^^^^^^^^^^^^
  File "/home/siddharth/SixSense/venv/lib/python3.12/site-packages/httpx/_transports/default.py", line 249, in handle_request
    with map_httpcore_exceptions():
  File "/usr/lib/python3.12/contextlib.py", line 158, in __exit__
    self.gen.throw(value)
  File "/home/siddharth/SixSense/venv/lib/python3.12/site-packages/httpx/_transports/default.py", line 118, in map_httpcore_exceptions
    raise mapped_exc(message) from exc
httpx.ConnectTimeout: timed out
